Workbook
Name CostPerTrip: "Inputs!$B$36"
Name HoursPerMonth: "Inputs!$B$20"
Name HoursPerUnit: "Inputs!$B$26"
Name MonthlyTools: "Inputs!$B$43"
Name OneTimeEquip: "Inputs!$B$44"
Name POCCost: "Inputs!$B$32"
Name Revenue: "Inputs!$B$24"
Name RiskReserve: "Inputs!$B$28"
Name ScA_DevMonths: "Inputs!$B$58"
Name ScA_Floor: "Inputs!$B$49"
Name ScA_OffDev: "Inputs!$B$56"
Name ScA_OffStab: "Inputs!$B$57"
Name ScA_StabMonths: "Inputs!$B$59"
Name ScA_Target: "Inputs!$B$48"
Name ScA_TotalPostPOC: "Inputs!$B$60"
Name ScB_DevMonths: "Inputs!$C$58"
Name ScB_Floor: "Inputs!$B$51"
Name ScB_OffDev: "Inputs!$C$56"
Name ScB_OffStab: "Inputs!$C$57"
Name ScB_StabMonths: "Inputs!$C$59"
Name ScB_Target: "Inputs!$B$50"
Name ScB_TotalPostPOC: "Inputs!$C$60"
Name TotalHours: "Inputs!$B$27"
Name TotalScreens: "Inputs!$B$25"
Name TotalUnits: "Inputs!$B$25"
Name TripsA: "Inputs!$B$37"
Name TripsB: "Inputs!$B$38"

Sheet Instructions
A1: PROJECT COSTING WORKBOOK
A2: BayOne Solutions — Outcome-Based Engagement Pricing
A4: PURPOSE
A5: This workbook models the internal cost of delivering an outcome-based consulting engagement. It helps you determine whether a quoted price supports your target margin at a given team structure and timeline. It models two delivery scenarios (shorter vs. longer timeline) and a discount sensitivity analysis for the longer-timeline option.
A7: HOW TO USE
A8: 1. Start on the INPUTS tab. Fill in your project details, personnel rates, and scenario parameters. 2. The SCENARIO A and SCENARIO B tabs auto-calculate based on your inputs. 3. Use the DISCOUNT ANALYSIS tab to see how much room you have to negotiate on price. 4. The COMPARISON tab gives you a side-by-side view of all scenarios. 5. The THROUGHPUT tab validates whether your team can actually deliver the scope in the timeline.
A10: KEY CONCEPTS
A11: Allocation % This is a COST ALLOCATION mechanism, not a productivity measure. If a person is 50% allocated, it means 50% of their cost is charged to this project. The other 50% is charged elsewhere. The person still works full-time. Allocation splits cost across projects.
A12: Rate Type (Annual vs. Hourly) Each resource is either salaried (Annual) or contracted (Hourly). This determines how the Loaded Monthly cost is calculated: - Annual: Loaded Annual / 12 - Hourly: Loaded Hourly × Working Hours per Month
A13: Risk Reserve A percentage buffer added on top of base cost to account for scope creep, technical complexity, and unknowns. This is not a guaranteed spend. It sits inside the gross margin as protection. If nothing goes wrong, the risk reserve becomes additional margin.
A14: Stabilization & Acceptance The final phase of each scenario. This is NOT a separate QA phase. Development is agile and testing happens throughout. This buffer covers production-level validation after client integration, bug fixes, stakeholder demos, and final acceptance.
A15: Base Cost vs. Loaded Cost - Base Cost = Personnel + Travel + Hardware/Consumables (what you expect to spend) - Loaded Cost = Base Cost + Risk Reserve (worst-case budget) - Margin on Base = best case (if risk doesn't materialize) - Margin on Loaded = worst case (if full risk reserve is consumed)
... A24: This workbook ships with sample data for a fictional engagement. Clear the sample data on the Inputs tab and replace with your project details. All scenario tabs will update automatically.

Sheet Inputs
A1: Project Details
A2: Project Name | B2: Acme Corp Platform Migration
A3: Client | B3: Acme Corporation
A4: Engagement Type | B4: Legacy Platform Conversion
A5: Deliverable | B5: 120 screens, full-stack (UI + backend)
A6: Pricing Model | B6: Outcome-based, fixed price
A9: Personnel Rates
A10: Resource | B10: Rate Type | C10: Base Rate | D10: Load Factor | E10: Loaded Rate | F10: Loaded Monthly | G10: Allocation % | H10: Effective Monthly
A11: Project Lead | B11: Annual | C11: 150000 | D11: 1.2 | E11: =C11*D11 -> 180000 | F11: =IF(B11="Annual",E11/12,E11*B20) -> 15000 | G11: 0.25 | H11: =F11*G11 -> 3750
A12: Senior Engineer (US) | B12: Annual | C12: 120000 | D12: 1.2 | E12: =C12*D12 -> 144000 | F12: =IF(B12="Annual",E12/12,E12*B20) -> 12000 | G12: 1 | H12: =F12*G12 -> 12000
A13: Offshore Engineer 1 | B13: Hourly | C13: 30 | D13: 1.2 | E13: =C13*D13 -> 36 | F13: =IF(B13="Annual",E13/12,E13*B20) -> 6239.88 | G13: 1 | H13: =F13*G13 -> 6239.88
A14: Offshore Engineer 2 | B14: Hourly | C14: 25 | D14: 1.2 | E14: =C14*D14 -> 30 | F14: =IF(B14="Annual",E14/12,E14*B20) -> 5199.9 | G14: 1 | H14: =F14*G14 -> 5199.9
A15: Offshore Engineer 3 | B15: Hourly | C15: 28 | D15: 1.2 | E15: =C15*D15 -> 33.6 | F15: =IF(B15="Annual",E15/12,E15*B20) -> 5823.888 | G15: 1 | H15: =F15*G15 -> 5823.888
A18: Constants
A19: Load Factor (default) | B19: 1.2
A20: Working Hours per Month | B20: 173.33
A23: Engagement Parameters
A24: Revenue | B24: 350000
A25: Total Deliverable Units (screens, modules, etc.) | B25: 120
A26: Hours per Unit (estimated, with tooling) | B26: 10
A27: Total Delivery Hours | B27: =B25*B26 -> 1200
A28: Risk Reserve % | B28: 0.25
A29: POC Duration (months) | B29: 1
A30: POC Resource | B30: Project Lead
A31: POC Hours | B31: 60
A32: POC Cost (absorbed) | B32: =B31*(Inputs!E11/2080) -> 5192.3077
A35: Travel & Expenses
A36: Cost per Trip | B36: 2500
A37: Trips (Scenario A) | B37: 2
A38: Trips (Scenario B) | B38: 3
A39: Travel Destination | B39: Client HQ
A42: Hardware & Consumables
A43: Monthly Tools & Subscriptions | B43: 0
A44: One-Time Equipment | B44: 0
A47: Margin Thresholds
A48: Scenario A Target (ideal) | B48: 0.4
A49: Scenario A Floor | B49: 0.4
A50: Scenario B Target (ideal) | B50: 0.4
A51: Scenario B Floor (minimum acceptable) | B51: 0.3
A54: Scenario Parameters
...

Sheet Scenario A
A1: ="Scenario A: "&Inputs!B55&" — Accelerated Delivery (More Resources, Shorter Timeline)" -> Scenario A: Q3 Delivery — Accelerated Delivery (More Resources, Shorter Timeline)
A2: ="POC (1 month) + "&Inputs!B58&" dev months + "&Inputs!B59&" stabilization month(s) = "&(1+Inputs!B60)&" months total" -> POC (1 month) + 2 dev months + 1 stabilization month(s) = 4 months total
A4: Resource | B4: Month 1 (POC) | C4: Month 2 | D4: Month 3 | E4: Month 4 (Stab.) | F4: Total
A5: Project Lead | B5: =Inputs!B32 -> 5192.3077 | C5: =Inputs!H11 -> 3750 | D5: =Inputs!H11 -> 3750 | E5: =Inputs!H11 -> 3750 | F5: =SUM(B5:E5) -> 16442.308
A6: Senior Engineer (US) | B6: 0 | C6: =Inputs!H12 -> 12000 | D6: =Inputs!H12 -> 12000 | E6: =Inputs!H12 -> 12000 | F6: =SUM(B6:E6) -> 36000
A7: Offshore Engineers (dev) | B7: 0 | C7: =AVERAGE(Inputs!H13:H15)*Inputs!B56 -> 28772.78 | D7: =AVERAGE(Inputs!H13:H15)*Inputs!B56 -> 28772.78 | E7: 0 | F7: =SUM(B7:E7) -> 57545.56
A8: Offshore Engineers (stab.) | B8: 0 | C8: 0 | D8: 0 | E8: =AVERAGE(Inputs!H13:H15)*Inputs!B57 -> 23018.224 | F8: =SUM(B8:E8) -> 23018.224
A9: Personnel Total | B9: =SUM(B5:B8) -> 5192.3077 | C9: =SUM(C5:C8) -> 44522.78 | D9: =SUM(D5:D8) -> 44522.78 | E9: =SUM(E5:E8) -> 38768.224 | F9: =SUM(F5:F8) -> 133006.09
A10: Cumulative | B10: =B9 -> 5192.3077 | C10: =B10+C9 -> 49715.088 | D10: =C10+D9 -> 94237.868 | E10: =D10+E9 -> 133006.09
A13: Financial Summary
A14: Revenue | B14: =Inputs!B24 -> 350000
A15: Personnel Cost | B15: =F9 -> 133006.09
A16: Travel & Expenses | B16: =Inputs!B36*Inputs!B37 -> 5000
A17: Hardware & Consumables | B17: =Inputs!B44+(Inputs!B43*(1+Inputs!B60)) -> 0
A18: Base Cost | B18: =SUM(B15:B17) -> 138006.09
A19: Risk Reserve | B19: =B18*Inputs!B28 -> 34501.523
A20: Loaded Cost | B20: =B18+B19 -> 172507.61
A22: Margin on Loaded Cost ($) | B22: =B14-B20 -> 177492.39
A23: Margin on Loaded Cost (%) | B23: =B22/B14 -> 0.5071211
A24: Margin on Base Cost ($) | B24: =B14-B18 -> 211993.91
A25: Margin on Base Cost (%) | B25: =B24/B14 -> 0.60569688
A27: Above Floor? (loaded) | B27: =IF(B23>=Inputs!B49,"YES","NO") -> YES
A28: Above Floor? (base) | B28: =IF(B25>=Inputs!B49,"YES","NO") -> YES
A31: Per-Unit Economics
A32: Cost per Unit (base) | B32: =B18/Inputs!B25 -> 1150.0508
A33: Cost per Unit (loaded) | B33: =B20/Inputs!B25 -> 1437.5635
A34: Revenue per Unit | B34: =B14/Inputs!B25 -> 2916.6667
A35: Margin per Unit | B35: =B34-B33 -> 1479.1032
A38: Staffing Summary
A39: Total Duration (months) | B39: =1+Inputs!B60 -> 4
A40: Peak Headcount | B40: =2+Inputs!B56 -> 7
A41: Peak Monthly Burn | B41: =MAX(B9:E9) -> 44522.78
A42: Avg Monthly Burn | B42: =F9/B39 -> 33251.523

Sheet Scenario B
A1: ="Scenario B: "&Inputs!C55&" — Extended Timeline (Fewer Resources, Longer Duration)" -> Scenario B: Q4 Delivery — Extended Timeline (Fewer Resources, Longer Duration)
A2: ="POC (1 month) + "&Inputs!C58&" dev months + "&Inputs!C59&" stabilization months = "&(1+Inputs!C60)&" months total" -> POC (1 month) + 5 dev months + 2 stabilization months = 8 months total
A4: Resource | B4: Month 1 (POC) | C4: Month 2 | D4: Month 3 | E4: Month 4 | F4: Month 5 | G4: Month 6 | H4: Month 7 (Stab.) | I4: Month 8 (Stab.) | J4: Total
A5: Project Lead | B5: =Inputs!B32 -> 5192.3077 | C5: =Inputs!H11 -> 3750 | D5: =Inputs!H11 -> 3750 | E5: =Inputs!H11 -> 3750 | F5: =Inputs!H11 -> 3750 | G5: =Inputs!H11 -> 3750 | H5: =Inputs!H11 -> 3750 | I5: =Inputs!H11 -> 3750 | J5: =SUM(B5:I5) -> 31442.308
A6: Senior Engineer (US) | B6: 0 | C6: =Inputs!H12 -> 12000 | D6: =Inputs!H12 -> 12000 | E6: =Inputs!H12 -> 12000 | F6: =Inputs!H12 -> 12000 | G6: =Inputs!H12 -> 12000 | H6: =Inputs!H12*0.5 -> 6000 | I6: =Inputs!H12*0.5 -> 6000 | J6: =SUM(B6:I6) -> 72000
A7: Offshore Engineers (dev) | B7: 0 | C7: =AVERAGE(Inputs!H13:H15)*Inputs!C56 -> 11509.112 | D7: =AVERAGE(Inputs!H13:H15)*Inputs!C56 -> 11509.112 | E7: =AVERAGE(Inputs!H13:H15)*Inputs!C56 -> 11509.112 | F7: =AVERAGE(Inputs!H13:H15)*Inputs!C56 -> 11509.112 | G7: =AVERAGE(Inputs!H13:H15)*Inputs!C56 -> 11509.112 | H7: 0 | I7: 0 | J7: =SUM(B7:I7) -> 57545.56
A8: Offshore Engineers (stab.) | B8: 0 | C8: 0 | D8: 0 | E8: 0 | F8: 0 | G8: 0 | H8: =AVERAGE(Inputs!H13:H15)*Inputs!C57 -> 11509.112 | I8: =AVERAGE(Inputs!H13:H15)*Inputs!C57 -> 11509.112 | J8: =SUM(B8:I8) -> 23018.224
A9: Personnel Total | B9: =SUM(B5:B8) -> 5192.3077 | C9: =SUM(C5:C8) -> 27259.112 | D9: =SUM(D5:D8) -> 27259.112 | E9: =SUM(E5:E8) -> 27259.112 | F9: =SUM(F5:F8) -> 27259.112 | G9: =SUM(G5:G8) -> 27259.112 | H9: =SUM(H5:H8) -> 21259.112 | I9: =SUM(I5:I8) -> 21259.112 | J9: =SUM(J5:J8) -> 184006.09
A10: Cumulative | B10: =B9 -> 5192.3077 | C10: =B10+C9 -> 32451.42 | D10: =C10+D9 -> 59710.532 | E10: =D10+E9 -> 86969.644 | F10: =E10+F9 -> 114228.76 | G10: =F10+G9 -> 141487.87 | H10: =G10+H9 -> 162746.98 | I10: =H10+I9 -> 184006.09
A13: Financial Summary
A14: Revenue | B14: =Inputs!B24 -> 350000
A15: Personnel Cost | B15: =J9 -> 184006.09
A16: Travel & Expenses | B16: =Inputs!B36*Inputs!B38 -> 7500
A17: Hardware & Consumables | B17: =Inputs!B44+(Inputs!B43*(1+Inputs!C60)) -> 0
A18: Base Cost | B18: =SUM(B15:B17) -> 191506.09
A19: Risk Reserve | B19: =B18*Inputs!B28 -> 47876.523
A20: Loaded Cost | B20: =B18+B19 -> 239382.61
A22: Margin on Loaded Cost ($) | B22: =B14-B20 -> 110617.39
A23: Margin on Loaded Cost (%) | B23: =B22/B14 -> 0.31604967
A24: Margin on Base Cost ($) | B24: =B14-B18 -> 158493.91
A25: Margin on Base Cost (%) | B25: =B24/B14 -> 0.45283974
A27: Above Floor? (loaded) | B27: =IF(B23>=Inputs!B51,"YES","NO") -> YES
A28: Above Floor? (base) | B28: =IF(B25>=Inputs!B51,"YES","NO") -> YES
A31: Per-Unit Economics
A32: Cost per Unit (base) | B32: =B18/Inputs!B25 -> 1595.8841
A33: Cost per Unit (loaded) | B33: =B20/Inputs!B25 -> 1994.8551
A34: Revenue per Unit | B34: =B14/Inputs!B25 -> 2916.6667
A35: Margin per Unit | B35: =B34-B33 -> 921.81154
A38: Staffing Summary
A39: Total Duration (months) | B39: =1+Inputs!C60 -> 8
A40: Peak Headcount | B40: =2+Inputs!C56 -> 4
A41: Peak Monthly Burn | B41: =MAX(B9:I9) -> 27259.112
A42: Avg Monthly Burn | B42: =J9/B39 -> 23000.761

Sheet Discount Analysis
A1: Discount Sensitivity — Scenario B Timeline Only
A3: Base Cost (from Scenario B): | B3: ='Scenario B'!B18 -> 191506.09
A4: Loaded Cost (from Scenario B): | B4: ='Scenario B'!B20 -> 239382.61
A6: Price | B6: Discount % | C6: Margin $ (loaded) | D6: Margin % (loaded) | E6: Margin $ (base) | F6: Margin % (base) | G6: Verdict
A7: =Inputs!B24*(1-0) -> 350000 | B7: 0 | C7: =A7-$B$4 -> 110617.39 | D7: =C7/A7 -> 0.31604967 | E7: =A7-$B$3 -> 158493.91 | F7: =E7/A7 -> 0.45283974 | G7: =IF(D7>=Inputs!B51,"SAFE","BELOW FLOOR") -> SAFE
A8: =Inputs!B24*(1-0.05) -> 332500 | B8: 0.05 | C8: =A8-$B$4 -> 93117.385 | D8: =C8/A8 -> 0.28005229 | E8: =A8-$B$3 -> 140993.91 | F8: =E8/A8 -> 0.42404183 | G8: =IF(D8>=Inputs!B51,"SAFE","BELOW FLOOR") -> BELOW FLOOR
A9: =Inputs!B24*(1-0.1) -> 315000 | B9: 0.1 | C9: =A9-$B$4 -> 75617.385 | D9: =C9/A9 -> 0.24005519 | E9: =A9-$B$3 -> 123493.91 | F9: =E9/A9 -> 0.39204415 | G9: =IF(D9>=Inputs!B51,"SAFE","BELOW FLOOR") -> BELOW FLOOR
A10: =Inputs!B24*(1-0.15) -> 297500 | B10: 0.15 | C10: =A10-$B$4 -> 58117.385 | D10: =C10/A10 -> 0.19535256 | E10: =A10-$B$3 -> 105993.91 | F10: =E10/A10 -> 0.35628204 | G10: =IF(D10>=Inputs!B51,"SAFE","BELOW FLOOR") -> BELOW FLOOR
A11: =Inputs!B24*(1-0.2) -> 280000 | B11: 0.2 | C11: =A11-$B$4 -> 40617.385 | D11: =C11/A11 -> 0.14506209 | E11: =A11-$B$3 -> 88493.908 | F11: =E11/A11 -> 0.31604967 | G11: =IF(D11>=Inputs!B51,"SAFE","BELOW FLOOR") -> BELOW FLOOR
A12: =Inputs!B24*(1-0.25) -> 262500 | B12: 0.25 | C12: =A12-$B$4 -> 23117.385 | D12: =C12/A12 -> 0.08806623 | E12: =A12-$B$3 -> 70993.908 | F12: =E12/A12 -> 0.27045298 | G12: =IF(D12>=Inputs!B51,"SAFE","BELOW FLOOR") -> BELOW FLOOR
A13: =Inputs!B24*(1-0.3) -> 245000 | B13: 0.3 | C13: =A13-$B$4 -> 5617.3854 | D13: =C13/A13 -> 0.022928104 | E13: =A13-$B$3 -> 53493.908 | F13: =E13/A13 -> 0.21834248 | G13: =IF(D13>=Inputs!B51,"SAFE","BELOW FLOOR") -> BELOW FLOOR
A16: Floor Prices
A17: Floor at margin target (loaded) | B17: =B4/(1-Inputs!B51) -> 341975.16
A18: Max discount % (loaded) | B18: =1-(B17/Inputs!B24) -> 0.022928104
A19: Floor at margin target (base) | B19: =B3/(1-Inputs!B51) -> 273580.13
A20: Max discount % (base) | B20: =1-(B19/Inputs!B24) -> 0.21834248

Sheet Comparison
A1: Scenario Comparison Dashboard
A3: Metric | B3: Scenario A | C3: Scenario B | D3: Discount (floor)
A4: Revenue | B4: ='Scenario A'!B14 -> 350000 | C4: ='Scenario B'!B14 -> 350000 | D4: ='Discount Analysis'!B17 -> 341975.16
A5: Base Cost | B5: ='Scenario A'!B18 -> 138006.09 | C5: ='Scenario B'!B18 -> 191506.09 | D5: ='Scenario B'!B18 -> 191506.09
A6: Risk Reserve | B6: ='Scenario A'!B19 -> 34501.523 | C6: ='Scenario B'!B19 -> 47876.523 | D6: ='Scenario B'!B19 -> 47876.523
A7: Loaded Cost | B7: ='Scenario A'!B20 -> 172507.61 | C7: ='Scenario B'!B20 -> 239382.61 | D7: ='Scenario B'!B20 -> 239382.61
A8: Margin % (loaded) | B8: ='Scenario A'!B23 -> 0.5071211 | C8: ='Scenario B'!B23 -> 0.31604967 | D8: =(D4-D7)/D4 -> 0.3
A9: Margin % (base) | B9: ='Scenario A'!B25 -> 0.60569688 | C9: ='Scenario B'!B25 -> 0.45283974 | D9: =(D4-D5)/D4 -> 0.44
A10: Duration (months) | B10: ='Scenario A'!B39 -> 4 | C10: ='Scenario B'!B39 -> 8 | D10: ='Scenario B'!B39 -> 8
A11: Peak Headcount | B11: ='Scenario A'!B40 -> 7 | C11: ='Scenario B'!B40 -> 4 | D11: ='Scenario B'!B40 -> 4
A12: Cost per Unit (loaded) | B12: ='Scenario A'!B33 -> 1437.5635 | C12: ='Scenario B'!B33 -> 1994.8551 | D12: ='Scenario B'!B33 -> 1994.8551
A13: Revenue per Unit | B13: ='Scenario A'!B34 -> 2916.6667 | C13: ='Scenario B'!B34 -> 2916.6667 | D13: =D4/Inputs!B25 -> 2849.793
A14: Avg Monthly Burn | B14: ='Scenario A'!B42 -> 33251.523 | C14: ='Scenario B'!B42 -> 23000.761 | D14: ='Scenario B'!B42 -> 23000.761
A15: Above Floor? (loaded) | B15: ='Scenario A'!B27 -> YES | C15: ='Scenario B'!B27 -> YES | D15: =IF(D8>=Inputs!B51,"YES","NO") -> YES

Sheet Throughput
A1: Delivery Throughput Validation
A3: Delivery Requirements
A4: Total Deliverable Units | B4: =Inputs!B25 -> 120
A5: Hours per Unit | B5: =Inputs!B26 -> 10
A6: Total Hours Needed | B6: =Inputs!B27 -> 1200
A9: Scenario A Capacity
A10: Offshore Engineers (dev phase) | B10: =Inputs!B56 -> 5
A11: Hours per Month per Engineer | B11: =Inputs!B20 -> 173.33
A12: Dev Months | B12: =Inputs!B58 -> 2
A13: Total Available Dev Hours | B13: =B10*B11*B12 -> 1733.3
A14: Units Possible | B14: =B13/B5 -> 173.33
A15: Utilization % | B15: =B4/B14 -> 0.69232101
A18: Scenario B Capacity
A19: Offshore Engineers (dev phase) | B19: =Inputs!C56 -> 2
A20: Hours per Month per Engineer | B20: =Inputs!B20 -> 173.33
A21: Dev Months | B21: =Inputs!C58 -> 5
A22: Total Available Dev Hours | B22: =B19*B20*B21 -> 1733.3
A23: Units Possible | B23: =B22/B5 -> 173.33
A24: Utilization % | B24: =B4/B23 -> 0.69232101
